<robot
  name="arm_desktop_A1">
  <link
    name="base_link">
    <inertial>
      <origin
        xyz="-0.0021483 0.0020648 0.03513"
        rpy="0 0 0" />
      <mass
        value="2.0387" />
      <inertia
        ixx="0.0034526"
        ixy="-5.4524E-06"
        ixz="2.871E-05"
        iyy="0.0037931"
        iyz="-3.465E-05"
        izz="0.0045898" />
    </inertial>
    <visual>
      <origin
        xyz="0 0 0"
        rpy="0 0 0" />
      <geometry>
        <mesh
          filename="package://arm_desktop_A1/meshes/base_link.STL" />
      </geometry>
      <material
        name="">
        <color
          rgba="0.75294 0.75294 0.75294 1" />
      </material>
    </visual>
    <collision>
      <origin
        xyz="0 0 0"
        rpy="0 0 0" />
      <geometry>
        <mesh
          filename="package://arm_desktop_A1/meshes/base_link.STL" />
      </geometry>
    </collision>
  </link>
  <link
    name="Link2">
    <inertial>
      <origin
        xyz="0.0394425624935786 -0.0291988063958786 0.0760948891563128"
        rpy="0 0 0" />
      <mass
        value="1.08391675471565" />
      <inertia
        ixx="0.00127381232434219"
        ixy="0.000231086962801532"
        ixz="-0.00053899995189878"
        iyy="0.00180581909684817"
        iyz="0.000364400312722063"
        izz="0.00136704670584597" />
    </inertial>
    <visual>
      <origin
        xyz="0 0 0"
        rpy="0 0 0" />
      <geometry>
        <mesh
          filename="package://arm_desktop_A1/meshes/Link2.STL" />
      </geometry>
      <material
        name="">
        <color
          rgba="0.752941176470588 0.752941176470588 0.752941176470588 1" />
      </material>
    </visual>
    <collision>
      <origin
        xyz="0 0 0"
        rpy="0 0 0" />
      <geometry>
        <mesh
          filename="package://arm_desktop_A1/meshes/Link2.STL" />
      </geometry>
    </collision>
  </link>
  <joint
    name="a"
    type="revolute">
    <origin
      xyz="0 0 0.0835"
      rpy="-3.2394E-18 3.3101E-17 -1.6683" />
    <parent
      link="base_link" />
    <child
      link="Link2" />
    <axis
      xyz="0 0 1" />
    <limit
      lower="-3.14"
      upper="3.14"
      effort="0"
      velocity="0" />
  </joint>
  <link
    name="Link3">
    <inertial>
      <origin
        xyz="-3.4535E-05 0.16228 -0.024396"
        rpy="0 0 0" />
      <mass
        value="1.2325" />
      <inertia
        ixx="0.0093196"
        ixy="1.925E-06"
        ixz="-7.8804E-07"
        iyy="0.0026647"
        iyz="0.0028774"
        izz="0.0071078" />
    </inertial>
    <visual>
      <origin
        xyz="0 0 0"
        rpy="0 0 0" />
      <geometry>
        <mesh
          filename="package://arm_desktop_A1/meshes/Link3.STL" />
      </geometry>
      <material
        name="">
        <color
          rgba="0.75294 0.75294 0.75294 1" />
      </material>
    </visual>
    <collision>
      <origin
        xyz="0 0 0"
        rpy="0 0 0" />
      <geometry>
        <mesh
          filename="package://arm_desktop_A1/meshes/Link3.STL" />
      </geometry>
    </collision>
  </link>
  <joint
    name="b"
    type="revolute">
    <origin
      xyz="-0.012277 -0.041393 0.0895"
      rpy="1.5708 -5.5511E-17 1.6683" />
    <parent
      link="Link2" />
    <child
      link="Link3" />
    <axis
      xyz="0 0 1" />
    <limit
      lower="-1.57"
      upper="1"
      effort="0"
      velocity="0" />
  </joint>
  <link
    name="Link4">
    <inertial>
      <origin
        xyz="0.0743591859793955 0.0694419689975732 -0.0463501773283954"
        rpy="0 0 0" />
      <mass
        value="0.764787699105475" />
      <inertia
        ixx="0.00069070087139733"
        ixy="-0.000185702650745451"
        ixz="1.08350168983949E-05"
        iyy="0.00103518677288356"
        iyz="8.2836271543237E-06"
        izz="0.00122454437016658" />
    </inertial>
    <visual>
      <origin
        xyz="0 0 0"
        rpy="0 0 0" />
      <geometry>
        <mesh
          filename="package://arm_desktop_A1/meshes/Link4.STL" />
      </geometry>
      <material
        name="">
        <color
          rgba="0.752941176470588 0.752941176470588 0.752941176470588 1" />
      </material>
    </visual>
    <collision>
      <origin
        xyz="0 0 0"
        rpy="0 0 0" />
      <geometry>
        <mesh
          filename="package://arm_desktop_A1/meshes/Link4.STL" />
      </geometry>
    </collision>
  </link>
  <joint
    name="c"
    type="revolute">
    <origin
      xyz="-5E-05 0.20668 0.02"
      rpy="0 0 0" />
    <parent
      link="Link3" />
    <child
      link="Link4" />
    <axis
      xyz="0 0 1" />
    <limit
      lower="-1"
      upper="1.57"
      effort="0"
      velocity="0" />
  </joint>
  <link
    name="Link5">
    <inertial>
      <origin
        xyz="0.000841050166545981 4.0885738206875E-05 0.123675519546273"
        rpy="0 0 0" />
      <mass
        value="0.349387530622796" />
      <inertia
        ixx="0.00123273062711949"
        ixy="-3.42068238205955E-09"
        ixz="-2.71446030975722E-05"
        iyy="0.00122895528186877"
        iyz="-4.12560013252845E-07"
        izz="0.000196818796686809" />
    </inertial>
    <visual>
      <origin
        xyz="0 0 0"
        rpy="0 0 0" />
      <geometry>
        <mesh
          filename="package://arm_desktop_A1/meshes/Link5.STL" />
      </geometry>
      <material
        name="">
        <color
          rgba="0.752941176470588 0.752941176470588 0.752941176470588 1" />
      </material>
    </visual>
    <collision>
      <origin
        xyz="0 0 0"
        rpy="0 0 0" />
      <geometry>
        <mesh
          filename="package://arm_desktop_A1/meshes/Link5.STL" />
      </geometry>
    </collision>
  </link>
  <joint
    name="d"
    type="revolute">
    <origin
      xyz="0.11743 0.073853 -0.0465"
      rpy="0 1.5708 0" />
    <parent
      link="Link4" />
    <child
      link="Link5" />
    <axis
      xyz="0 0 -1" />
    <limit
      lower="-3.14"
      upper="3.14"
      effort="0"
      velocity="0" />
  </joint>
  <link
    name="Link6">
    <inertial>
      <origin
        xyz="-0.0373940256260459 0.000667387762520122 0.0109212297403901"
        rpy="0 0 0" />
      <mass
        value="0.0722230137267348" />
      <inertia
        ixx="3.16017266827191E-05"
        ixy="8.7189548653765E-07"
        ixz="1.62694922923443E-05"
        iyy="5.920538735604E-05"
        iyz="-1.12476772871054E-07"
        izz="5.05590815561523E-05" />
    </inertial>
    <visual>
      <origin
        xyz="0 0 0"
        rpy="0 0 0" />
      <geometry>
        <mesh
          filename="package://arm_desktop_A1/meshes/Link6.STL" />
      </geometry>
      <material
        name="">
        <color
          rgba="0.752941176470588 0.752941176470588 0.752941176470588 1" />
      </material>
    </visual>
    <collision>
      <origin
        xyz="0 0 0"
        rpy="0 0 0" />
      <geometry>
        <mesh
          filename="package://arm_desktop_A1/meshes/Link6.STL" />
      </geometry>
    </collision>
  </link>
  <joint
    name="e"
    type="revolute">
    <origin
      xyz="-0.01575 0 0.19605"
      rpy="0 1.5708 0" />
    <parent
      link="Link5" />
    <child
      link="Link6" />
    <axis
      xyz="0 0 -1" />
    <limit
      lower="-1.57"
      upper="1.57"
      effort="0"
      velocity="0" />
  </joint>
  <link
    name="L_Link">
    <inertial>
      <origin
        xyz="-0.0461881695254263 -0.0090997957153062 -0.0266364859197706"
        rpy="0 0 0" />
      <mass
        value="0.0210070673697344" />
      <inertia
        ixx="1.2470588229014E-05"
        ixy="-1.86210501807309E-07"
        ixz="3.5401578286979E-08"
        iyy="2.690075033744E-05"
        iyz="6.9746612926437E-09"
        izz="1.78032254856216E-05" />
    </inertial>
    <visual>
      <origin
        xyz="0 0 0"
        rpy="0 0 0" />
      <geometry>
        <mesh
          filename="package://arm_desktop_A1/meshes/L_Link.STL" />
      </geometry>
      <material
        name="">
        <color
          rgba="1 0.6 0 1" />
      </material>
    </visual>
    <collision>
      <origin
        xyz="0 0 0"
        rpy="0 0 0" />
      <geometry>
        <mesh
          filename="package://arm_desktop_A1/meshes/L_Link.STL" />
      </geometry>
    </collision>
  </link>
  <joint
    name="f"
    type="revolute">
    <origin
      xyz="-0.055118 0.027 0.03245"
      rpy="-1.5708 5.2736E-16 4.1935E-17" />
    <parent
      link="Link6" />
    <child
      link="L_Link" />
    <axis
      xyz="0 0 1" />
    <limit
      lower="-0.7"
      upper="0.7"
      effort="0"
      velocity="0" />
  </joint>
  <link
    name="R_Link">
    <inertial>
      <origin
        xyz="-0.046331 0.0089356 -0.029044"
        rpy="0 0 0" />
      <mass
        value="0.020942" />
      <inertia
        ixx="1.2124E-05"
        ixy="1.248E-07"
        ixz="2.0932E-07"
        iyy="2.6408E-05"
        iyz="-6.0916E-08"
        izz="1.7682E-05" />
    </inertial>
    <visual>
      <origin
        xyz="0 0 0"
        rpy="0 0 0" />
      <geometry>
        <mesh
          filename="package://arm_desktop_A1/meshes/R_Link.STL" />
      </geometry>
      <material
        name="">
        <color
          rgba="0.3098 0.3098 0.3098 1" />
      </material>
    </visual>
    <collision>
      <origin
        xyz="0 0 0"
        rpy="0 0 0" />
      <geometry>
        <mesh
          filename="package://arm_desktop_A1/meshes/R_Link.STL" />
      </geometry>
    </collision>
  </link>
  <joint
    name="g"
    type="revolute">
    <origin
      xyz="-0.055118 0.03 0.00745"
      rpy="-1.5708 4.7184E-16 -4.0215E-16" />
    <parent
      link="Link6" />
    <child
      link="R_Link" />
    <axis
      xyz="0 0 1" />
    <limit
      lower="-0.8"
      upper="0.8"
      effort="0"
      velocity="0" />
	 <mimic joint="f" multiplier="-1.0" offset="0.0" />
  </joint>
   <link name="grasping_frame"/>
   <joint name="grasping_frame_joint" type="fixed">
   <parent link="Link6"/>
   <child link="grasping_frame"/>
   <origin xyz="-0.1 -0.0 0.015" rpy="0 0 0"/>
   </joint>
</robot>
